Workbook

Sheet HCLTECH
A1: DATE | B1: SERIES | C1: OPEN | D1: HIGH | E1: LOW | F1: PREV. CLOSE | G1: LTP | H1: CLOSE | I1: VWAP | J1: 52W H | K1: 52W L | L1: VOLUME | M1: VALUE | N1: NO. OF TRADES | O1: Daily Return
A2: 45474 | B2: EQ | C2: 1465 | D2: 1478.6 | E2: 1455 | F2: 1459.6 | G2: 1467 | H2: 1468.85 | I2: 1469.49 | J2: 1697.35 | K2: 1087.05 | L2: 3723295 | M2: 5.4713397e+09 | N2: 136363
A3: 45475 | B3: EQ | C3: 1475 | D3: 1492.45 | E3: 1473 | F3: 1468.85 | G3: 1479 | H3: 1480.8 | I3: 1483.06 | J3: 1697.35 | K3: 1087.05 | L3: 3811366 | M3: 5.652501e+09 | N3: 148852 | O3: =(H3-H2)/H2 -> 0.0081356163
A4: 45476 | B4: EQ | C4: 1489 | D4: 1489 | E4: 1471.2 | F4: 1480.8 | G4: 1482.1 | H4: 1481 | I4: 1481.18 | J4: 1697.35 | K4: 1087.05 | L4: 2070876 | M4: 3.0673396e+09 | N4: 96911 | O4: =(H4-H3)/H3 -> 0.00013506213
A5: 45477 | B5: EQ | C5: 1485 | D5: 1534.55 | E5: 1485 | F5: 1481 | G5: 1520 | H5: 1522.35 | I5: 1519.71 | J5: 1697.35 | K5: 1087.05 | L5: 6822557 | M5: 1.0368306e+10 | N5: 227299 | O5: =(H5-H4)/H4 -> 0.027920324
A6: 45478 | B6: EQ | C6: 1523 | D6: 1529.25 | E6: 1505.55 | F6: 1522.35 | G6: 1517.1 | H6: 1519.4 | I6: 1520.04 | J6: 1697.35 | K6: 1087.05 | L6: 3061687 | M6: 4.6538814e+09 | N6: 144035 | O6: =(H6-H5)/H5 -> -0.0019377935
A7: 45481 | B7: EQ | C7: 1528 | D7: 1540 | E7: 1506.2 | F7: 1519.4 | G7: 1537.95 | H7: 1533.4 | I7: 1520.96 | J7: 1697.35 | K7: 1087.05 | L7: 2939620 | M7: 4.4710461e+09 | N7: 124735 | O7: =(H7-H6)/H6 -> 0.0092141635
A8: 45482 | B8: EQ | C8: 1533.4 | D8: 1546.3 | E8: 1525 | F8: 1533.4 | G8: 1530 | H8: 1531.1 | I8: 1536.13 | J8: 1697.35 | K8: 1087.05 | L8: 2658608 | M8: 4083958660 | N8: 117369 | O8: =(H8-H7)/H7 -> -0.0014999348
A9: 45483 | B9: EQ | C9: 1531.1 | D9: 1532.6 | E9: 1487.85 | F9: 1531.1 | G9: 1506.1 | H9: 1509.95 | I9: 1504.92 | J9: 1697.35 | K9: 1087.05 | L9: 3507096 | M9: 5.2778899e+09 | N9: 143838 | O9: =(H9-H8)/H8 -> -0.013813598
A10: 45484 | B10: EQ | C10: 1515 | D10: 1534 | E10: 1508.05 | F10: 1509.95 | G10: 1516.75 | H10: 1511.9 | I10: 1518.68 | J10: 1697.35 | K10: 1087.05 | L10: 3304053 | M10: 5.0178005e+09 | N10: 209418 | O10: =(H10-H9)/H9 -> 0.0012914335
A11: 45485 | B11: EQ | C11: 1530 | D11: 1566 | E11: 1510.5 | F11: 1511.9 | G11: 1561.75 | H11: 1560.2 | I11: 1550.48 | J11: 1697.35 | K11: 1087.05 | L11: 6430647 | M11: 9.9705579e+09 | N11: 298826 | O11: =(H11-H10)/H10 -> 0.031946557
A12: 45488 | B12: EQ | C12: 1580 | D12: 1636.4 | E12: 1567.4 | F12: 1560.2 | G12: 1568 | H12: 1569.6 | I12: 1596.87 | J12: 1697.35 | K12: 1095 | L12: 10337489 | M12: 16507600461 | N12: 369261 | O12: =(H12-H11)/H11 -> 0.0060248686
A13: 45489 | B13: EQ | C13: 1565 | D13: 1583 | E13: 1555 | F13: 1569.6 | G13: 1567.4 | H13: 1569.55 | I13: 1570.01 | J13: 1697.35 | K13: 1095 | L13: 3540661 | M13: 5.5588782e+09 | N13: 169358 | O13: =(H13-H12)/H12 -> -3.185525e-05
A14: 45491 | B14: EQ | C14: 1558.05 | D14: 1599.25 | E14: 1557 | F14: 1569.55 | G14: 1589 | H14: 1594.55 | I14: 1583.5 | J14: 1697.35 | K14: 1095 | L14: 4399468 | M14: 6.9665363e+09 | N14: 205545 | O14: =(H14-H13)/H13 -> 0.015928132
... A496: 46203 | B496: EQ | C496: 1102.5 | D496: 1105.7 | E496: 1068.6 | F496: 1102.4 | G496: 1072 | H496: 1071.8 | I496: 1079.17 | J496: 1780.1 | K496: 1068.6 | L496: 3794233 | M496: 4094623302 | N496: 129291 | O496: =(H496-H495)/H495 -> -0.02775762

Sheet ITC
A1: DATE | B1: SERIES | C1: OPEN | D1: HIGH | E1: LOW | F1: PREV. CLOSE | G1: LTP | H1: CLOSE | I1: VWAP | J1: 52W H | K1: 52W L | L1: VOLUME | M1: VALUE | N1: NO. OF TRADES | O1: Daily Return
A2: 45474 | B2: EQ | C2: 426.3 | D2: 430.25 | E2: 424.65 | F2: 424.9 | G2: 428.5 | H2: 429.05 | I2: 427.61 | J2: 499.7 | K2: 399.35 | L2: 12894747 | M2: 5.5139767e+09 | N2: 132870
A3: 45475 | B3: EQ | C3: 430 | D3: 430.65 | E3: 422.55 | F3: 429.05 | G3: 425.75 | H3: 425.5 | I3: 426.86 | J3: 499.7 | K3: 399.35 | L3: 10763335 | M3: 4.5944027e+09 | N3: 174096 | O3: =(H3-H2)/H2 -> -0.0082740939
A4: 45476 | B4: EQ | C4: 426.1 | D4: 429.65 | E4: 425.5 | F4: 425.5 | G4: 428.5 | H4: 428.3 | I4: 427.88 | J4: 499.7 | K4: 399.35 | L4: 7159756 | M4: 3.0635037e+09 | N4: 116001 | O4: =(H4-H3)/H3 -> 0.0065804935
A5: 45477 | B5: EQ | C5: 430 | D5: 431.5 | E5: 427.05 | F5: 428.3 | G5: 429.25 | H5: 429.05 | I5: 429.39 | J5: 499.7 | K5: 399.35 | L5: 9127340 | M5: 3.9191906e+09 | N5: 125047 | O5: =(H5-H4)/H4 -> 0.001751109
A6: 45478 | B6: EQ | C6: 429 | D6: 434 | E6: 427.6 | F6: 429.05 | G6: 433.5 | H6: 433.65 | I6: 431.98 | J6: 499.7 | K6: 399.35 | L6: 12929586 | M6: 5.5853597e+09 | N6: 151709 | O6: =(H6-H5)/H5 -> 0.010721361
A7: 45481 | B7: EQ | C7: 435.15 | D7: 444.55 | E7: 433.65 | F7: 433.65 | G7: 443.8 | H7: 443.6 | I7: 439.76 | J7: 499.7 | K7: 399.35 | L7: 20521107 | M7: 9.024462e+09 | N7: 194693 | O7: =(H7-H6)/H6 -> 0.022944771
A8: 45482 | B8: EQ | C8: 447.6 | D8: 455 | E8: 444 | F8: 443.6 | G8: 451.5 | H8: 452.6 | I8: 450.54 | J8: 499.7 | K8: 399.35 | L8: 26470260 | M8: 1.1925976e+10 | N8: 240760 | O8: =(H8-H7)/H7 -> 0.020288548
A9: 45483 | B9: EQ | C9: 453.7 | D9: 455.35 | E9: 446.5 | F9: 452.6 | G9: 450.3 | H9: 451.45 | I9: 450.95 | J9: 499.7 | K9: 399.35 | L9: 11618210 | M9: 5.2392577e+09 | N9: 155469 | O9: =(H9-H8)/H8 -> -0.0025408749
A10: 45484 | B10: EQ | C10: 450 | D10: 459.5 | E10: 448.7 | F10: 451.45 | G10: 458.6 | H10: 458.65 | I10: 456.02 | J10: 499.7 | K10: 399.35 | L10: 18831345 | M10: 8.5874376e+09 | N10: 283781 | O10: =(H10-H9)/H9 -> 0.01594861
A11: 45485 | B11: EQ | C11: 458.65 | D11: 463.25 | E11: 455.85 | F11: 458.65 | G11: 459.05 | H11: 459.05 | I11: 458.95 | J11: 499.7 | K11: 399.35 | L11: 18962800 | M11: 8.7030172e+09 | N11: 215367 | O11: =(H11-H10)/H10 -> 0.00087212471
A12: 45488 | B12: EQ | C12: 459.05 | D12: 466.45 | E12: 457.2 | F12: 459.05 | G12: 462.05 | H12: 463.4 | I12: 462.88 | J12: 499.7 | K12: 399.35 | L12: 16251032 | M12: 7.522328e+09 | N12: 154358 | O12: =(H12-H11)/H11 -> 0.0094760919
A13: 45489 | B13: EQ | C13: 463.45 | D13: 466.75 | E13: 461.4 | F13: 463.4 | G13: 465.7 | H13: 465.55 | I13: 464.53 | J13: 499.7 | K13: 399.35 | L13: 12996711 | M13: 6.0373705e+09 | N13: 137391 | O13: =(H13-H12)/H12 -> 0.0046396202
A14: 45491 | B14: EQ | C14: 463 | D14: 470.9 | E14: 462.65 | F14: 465.55 | G14: 470.5 | H14: 470.25 | I14: 467.91 | J14: 499.7 | K14: 399.35 | L14: 21094737 | M14: 9.8703744e+09 | N14: 196712 | O14: =(H14-H13)/H13 -> 0.010095586
... A496: 46203 | B496: EQ | C496: 291.5 | D496: 291.6 | E496: 285.5 | F496: 290.7 | G496: 287.3 | H496: 286.95 | I496: 287.55 | J496: 427 | K496: 275.05 | L496: 18180676 | M496: 5.2279385e+09 | N496: 433044 | O496: =(H496-H495)/H495 -> -0.012899897

Sheet HDFCBANK
A1: DATE | B1: SERIES | C1: OPEN | D1: HIGH | E1: LOW | F1: PREV. CLOSE | G1: LTP | H1: CLOSE | I1: VWAP | J1: 52W H | K1: 52W L | L1: VOLUME | M1: VALUE | N1: NO. OF TRADES | O1: Daily Return
A2: 45474 | B2: EQ | C2: 1680 | D2: 1707.3 | E2: 1680 | F2: 1683.8 | G2: 1704.2 | H2: 1705.2 | I2: 1699.74 | J2: 1757.5 | K2: 1363.55 | L2: 10593512 | M2: 1.800619e+10 | N2: 355235
A3: 45475 | B3: EQ | C3: 1715 | D3: 1734.9 | E3: 1702.75 | F3: 1705.2 | G3: 1728 | H3: 1730.6 | I3: 1722.46 | J3: 1757.5 | K3: 1363.55 | L3: 22960845 | M3: 3.9549118e+10 | N3: 486972 | O3: =(H3-H2)/H2 -> 0.014895613
A4: 45476 | B4: EQ | C4: 1791 | D4: 1794 | E4: 1764.65 | F4: 1730.6 | G4: 1767.7 | H4: 1768.65 | I4: 1776.87 | J4: 1794 | K4: 1363.55 | L4: 61608901 | M4: 1.0947088e+11 | N4: 846404 | O4: =(H4-H3)/H3 -> 0.021986594
A5: 45477 | B5: EQ | C5: 1759.75 | D5: 1759.75 | E5: 1724.85 | F5: 1768.65 | G5: 1728 | H5: 1727.15 | I5: 1735.22 | J5: 1794 | K5: 1363.55 | L5: 22924329 | M5: 3.9778717e+10 | N5: 405416 | O5: =(H5-H4)/H4 -> -0.023464224
A6: 45478 | B6: EQ | C6: 1685 | D6: 1685 | E6: 1642.2 | F6: 1727.15 | G6: 1649.4 | H6: 1648.1 | I6: 1656.79 | J6: 1794 | K6: 1363.55 | L6: 41121274 | M6: 6.8129239e+10 | N6: 1117072 | O6: =(H6-H5)/H5 -> -0.045769041
A7: 45481 | B7: EQ | C7: 1645.3 | D7: 1654.95 | E7: 1627.15 | F7: 1648.1 | G7: 1636.35 | H7: 1635.35 | I7: 1640.07 | J7: 1794 | K7: 1363.55 | L7: 19543900 | M7: 3.2053306e+10 | N7: 324769 | O7: =(H7-H6)/H6 -> -0.0077361811
A8: 45482 | B8: EQ | C8: 1625 | D8: 1646.7 | E8: 1620.35 | F8: 1635.35 | G8: 1638.8 | H8: 1636.5 | I8: 1638.53 | J8: 1794 | K8: 1363.55 | L8: 24275439 | M8: 3.9776085e+10 | N8: 442487 | O8: =(H8-H7)/H7 -> 0.00070321338
A9: 45483 | B9: EQ | C9: 1629.95 | D9: 1640 | E9: 1620.75 | F9: 1636.5 | G9: 1628.7 | H9: 1626.1 | I9: 1627.6 | J9: 1794 | K9: 1363.55 | L9: 22753591 | M9: 3.7033758e+10 | N9: 405034 | O9: =(H9-H8)/H8 -> -0.006355026
A10: 45484 | B10: EQ | C10: 1623.95 | D10: 1625.85 | E10: 1601 | F10: 1626.1 | G10: 1623 | H10: 1621.9 | I10: 1612.69 | J10: 1794 | K10: 1363.55 | L10: 22088537 | M10: 3.5621865e+10 | N10: 483343 | O10: =(H10-H9)/H9 -> -0.002582867
A11: 45485 | B11: EQ | C11: 1622 | D11: 1638.4 | E11: 1611.15 | F11: 1621.9 | G11: 1627.55 | H11: 1622.7 | I11: 1624.06 | J11: 1794 | K11: 1363.55 | L11: 28024980 | M11: 4.551422e+10 | N11: 332780 | O11: =(H11-H10)/H10 -> 0.00049324866
A12: 45488 | B12: EQ | C12: 1623.5 | D12: 1629.8 | E12: 1615.2 | F12: 1622.7 | G12: 1623 | H12: 1622.1 | I12: 1622 | J12: 1794 | K12: 1363.55 | L12: 16687847 | M12: 2.7067667e+10 | N12: 217738 | O12: =(H12-H11)/H11 -> -0.00036975411
A13: 45489 | B13: EQ | C13: 1620.75 | D13: 1627 | E13: 1616.8 | F13: 1622.1 | G13: 1621 | H13: 1619.75 | I13: 1621.84 | J13: 1794 | K13: 1363.55 | L13: 14475162 | M13: 2.3476342e+10 | N13: 269979 | O13: =(H13-H12)/H12 -> -0.0014487393
A14: 45491 | B14: EQ | C14: 1608 | D14: 1623.95 | E14: 1599.15 | F14: 1619.75 | G14: 1615 | H14: 1614.8 | I14: 1613.29 | J14: 1794 | K14: 1363.55 | L14: 16858532 | M14: 2.7197656e+10 | N14: 332318 | O14: =(H14-H13)/H13 -> -0.0030560272
... A496: 46203 | B496: EQ | C496: 806.1 | D496: 806.1 | E496: 792.75 | F496: 798.9 | G496: 800.45 | H496: 797.95 | I496: 798.65 | J496: 2037.7 | K496: 726.65 | L496: 45778356 | M496: 3.6561096e+10 | N496: 507833 | O496: =(H496-H495)/H495 -> -0.0011891351

Sheet MARUTI
A1: DATE | B1: SERIES | C1: OPEN | D1: HIGH | E1: LOW | F1: PREV. CLOSE | G1: LTP | H1: CLOSE | I1: VWAP | J1: 52W H | K1: 52W L | L1: VOLUME | M1: VALUE | N1: NO. OF TRADES | O1: Daily Return
A2: 45474 | B2: EQ | C2: 12045 | D2: 12260 | E2: 12005.55 | F2: 12033.85 | G2: 12100 | H2: 12108.65 | I2: 12124.61 | J2: 13073.95 | K2: 9254.15 | L2: 1134926 | M2: 1.3760539e+10 | N2: 122841
A3: 45475 | B3: EQ | C3: 12149.95 | D3: 12149.95 | E3: 11995 | F3: 12108.65 | G3: 12029.9 | H3: 12042.6 | I3: 12051.14 | J3: 13073.95 | K3: 9254.15 | L3: 687181 | M3: 8.2813116e+09 | N3: 67854 | O3: =(H3-H2)/H2 -> -0.0054547782
A4: 45476 | B4: EQ | C4: 12115 | D4: 12150 | E4: 11960 | F4: 12042.6 | G4: 12134 | H4: 12123.65 | I4: 12065.45 | J4: 13073.95 | K4: 9254.15 | L4: 467532 | M4: 5.6409837e+09 | N4: 53158 | O4: =(H4-H3)/H3 -> 0.0067302742
A5: 45477 | B5: EQ | C5: 12135 | D5: 12210 | E5: 12071.8 | F5: 12123.65 | G5: 12080 | H5: 12089.6 | I5: 12118.11 | J5: 13073.95 | K5: 9254.15 | L5: 299684 | M5: 3.6316035e+09 | N5: 46273 | O5: =(H5-H4)/H4 -> -0.0028085601
A6: 45478 | B6: EQ | C6: 12069.15 | D6: 12137.45 | E6: 12021.9 | F6: 12089.6 | G6: 12100 | H6: 12104.05 | I6: 12084.74 | J6: 13073.95 | K6: 9254.15 | L6: 406926 | M6: 4.9175964e+09 | N6: 75811 | O6: =(H6-H5)/H5 -> 0.0011952422
A7: 45481 | B7: EQ | C7: 12104 | D7: 12112 | E7: 11966 | F7: 12104.05 | G7: 12045 | H7: 12023.6 | I7: 12023.51 | J7: 13073.95 | K7: 9254.15 | L7: 496933 | M7: 5.974878e+09 | N7: 65581 | O7: =(H7-H6)/H6 -> -0.0066465357
A8: 45482 | B8: EQ | C8: 12325 | D8: 12959.95 | E8: 12264.05 | F8: 12023.6 | G8: 12807 | H8: 12827.7 | I8: 12709.23 | J8: 13073.95 | K8: 9254.15 | L8: 2114130 | M8: 2.6868957e+10 | N8: 244903 | O8: =(H8-H7)/H7 -> 0.066876809
A9: 45483 | B9: EQ | C9: 12950.05 | D9: 13300 | E9: 12732.65 | F9: 12827.7 | G9: 12780.25 | H9: 12772.8 | I9: 13027.14 | J9: 13300 | K9: 9254.15 | L9: 2070520 | M9: 2.6972955e+10 | N9: 252066 | O9: =(H9-H8)/H8 -> -0.0042798007
A10: 45484 | B10: EQ | C10: 12800 | D10: 12923.8 | E10: 12695.05 | F10: 12772.8 | G10: 12730.25 | H10: 12715.2 | I10: 12800.23 | J10: 13300 | K10: 9254.15 | L10: 608983 | M10: 7.7951199e+09 | N10: 100891 | O10: =(H10-H9)/H9 -> -0.0045095829
A11: 45485 | B11: EQ | C11: 12620 | D11: 12669.9 | E11: 12475 | F11: 12715.2 | G11: 12599 | H11: 12562.5 | I11: 12578.58 | J11: 13300 | K11: 9254.15 | L11: 674746 | M11: 8.4873496e+09 | N11: 93175 | O11: =(H11-H10)/H10 -> -0.012009249
A12: 45488 | B12: EQ | C12: 12600 | D12: 12768.5 | E12: 12590 | F12: 12562.5 | G12: 12645 | H12: 12643.95 | I12: 12673.77 | J12: 13300 | K12: 9254.15 | L12: 697192 | M12: 8.836054e+09 | N12: 79937 | O12: =(H12-H11)/H11 -> 0.0064835821
A13: 45489 | B13: EQ | C13: 12643 | D13: 12798 | E13: 12581.75 | F13: 12643.95 | G13: 12640 | H13: 12639.55 | I13: 12667.6 | J13: 13300 | K13: 9254.15 | L13: 347810 | M13: 4.405919e+09 | N13: 50006 | O13: =(H13-H12)/H12 -> -0.00034799252
A14: 45491 | B14: EQ | C14: 12633 | D14: 12680 | E14: 12463 | F14: 12639.55 | G14: 12651.45 | H14: 12644.05 | I14: 12593.75 | J14: 13300 | K14: 9254.15 | L14: 391216 | M14: 4.9268769e+09 | N14: 80921 | O14: =(H14-H13)/H13 -> 0.00035602533
... A496: 46203 | B496: EQ | C496: 13744 | D496: 14201 | E496: 13510 | F496: 13412 | G496: 14152 | H496: 14115 | I496: 13984.32 | J496: 17370 | K496: 12201 | L496: 1511415 | M496: 21136105823 | N496: 192999 | O496: =(H496-H495)/H495 -> 0.052415747

Sheet RELIANCE
A1: DATE | B1: SERIES | C1: OPEN | D1: HIGH | E1: LOW | F1: PREV. CLOSE | G1: LTP | H1: CLOSE | I1: VWAP | J1: 52W H | K1: 52W L | L1: VOLUME | M1: VALUE | N1: NO. OF TRADES | O1: Daily Return
A2: 45474 | B2: EQ | C2: 3125.05 | D2: 3158.8 | E2: 3111.35 | F2: 3130.8 | G2: 3123 | H2: 3120.3 | I2: 3126.53 | J2: 3162 | K2: 2220.3 | L2: 3862153 | M2: 1.2075137e+10 | N2: 186641
A3: 45475 | B3: EQ | C3: 3139 | D3: 3147 | E3: 3114 | F3: 3120.3 | G3: 3126.2 | H3: 3130.35 | I3: 3129.71 | J3: 3162 | K3: 2220.3 | L3: 3874623 | M3: 1.212643e+10 | N3: 179115 | O3: =(H3-H2)/H2 -> 0.0032208441
A4: 45476 | B4: EQ | C4: 3132.65 | D4: 3150 | E4: 3085.55 | F4: 3130.35 | G4: 3109 | H4: 3104.85 | I4: 3104.97 | J4: 3162 | K4: 2220.3 | L4: 4524810 | M4: 1.4049407e+10 | N4: 185754 | O4: =(H4-H3)/H3 -> -0.008146054
A5: 45477 | B5: EQ | C5: 3114 | D5: 3135 | E5: 3101.6 | F5: 3104.85 | G5: 3106 | H5: 3108.05 | I5: 3116.99 | J5: 3162 | K5: 2220.3 | L5: 3418588 | M5: 1.0655716e+10 | N5: 173336 | O5: =(H5-H4)/H4 -> 0.0010306456
A6: 45478 | B6: EQ | C6: 3107.65 | D6: 3197 | E6: 3096 | F6: 3108.05 | G6: 3189.9 | H6: 3177.25 | I6: 3149.82 | J6: 3197 | K6: 2220.3 | L6: 6134855 | M6: 1.9323716e+10 | N6: 261494 | O6: =(H6-H5)/H5 -> 0.022264764
A7: 45481 | B7: EQ | C7: 3178 | D7: 3217.6 | E7: 3165.05 | F7: 3177.25 | G7: 3201.5 | H7: 3201.8 | I7: 3195.83 | J7: 3217.6 | K7: 2220.3 | L7: 4750403 | M7: 1.5181479e+10 | N7: 240527 | O7: =(H7-H6)/H6 -> 0.0077268078
A8: 45482 | B8: EQ | C8: 3195.2 | D8: 3201 | E8: 3161 | F8: 3201.8 | G8: 3176.3 | H8: 3180.55 | I8: 3178.56 | J8: 3217.6 | K8: 2220.3 | L8: 3480001 | M8: 1.1061403e+10 | N8: 159638 | O8: =(H8-H7)/H7 -> -0.0066368917
A9: 45483 | B9: EQ | C9: 3190 | D9: 3195 | E9: 3126.3 | F9: 3180.55 | G9: 3164 | H9: 3168.45 | I9: 3154.77 | J9: 3217.6 | K9: 2220.3 | L9: 3567289 | M9: 1.1253968e+10 | N9: 182113 | O9: =(H9-H8)/H8 -> -0.0038043735
A10: 45484 | B10: EQ | C10: 3175 | D10: 3208.5 | E10: 3141 | F10: 3168.45 | G10: 3170 | H10: 3161.3 | I10: 3169.61 | J10: 3217.6 | K10: 2220.3 | L10: 5970473 | M10: 1.8924071e+10 | N10: 246252 | O10: =(H10-H9)/H9 -> -0.0022566239
A11: 45485 | B11: EQ | C11: 3169 | D11: 3210.3 | E11: 3149 | F11: 3161.3 | G11: 3195 | H11: 3193.45 | I11: 3186.07 | J11: 3217.6 | K11: 2220.3 | L11: 6462392 | M11: 2.0589634e+10 | N11: 246838 | O11: =(H11-H10)/H10 -> 0.010169867
A12: 45488 | B12: EQ | C12: 3208.9 | D12: 3211.7 | E12: 3171 | F12: 3193.45 | G12: 3193.6 | H12: 3194.45 | I12: 3191.4 | J12: 3217.6 | K12: 2220.3 | L12: 2664844 | M12: 8504591755 | N12: 187867 | O12: =(H12-H11)/H11 -> 0.00031314096
A13: 45489 | B13: EQ | C13: 3187 | D13: 3200 | E13: 3138.25 | F13: 3194.45 | G13: 3148.3 | H13: 3152.5 | I13: 3166.04 | J13: 3217.6 | K13: 2220.3 | L13: 4693419 | M13: 1.4859548e+10 | N13: 230262 | O13: =(H13-H12)/H12 -> -0.013132151
A14: 45491 | B14: EQ | C14: 3152 | D14: 3187.8 | E14: 3115.65 | F14: 3152.5 | G14: 3170.6 | H14: 3173.35 | I14: 3155.52 | J14: 3217.6 | K14: 2220.3 | L14: 6149187 | M14: 1.940391e+10 | N14: 212178 | O14: =(H14-H13)/H13 -> 0.0066137986
... A496: 46203 | B496: EQ | C496: 1306.9 | D496: 1306.9 | E496: 1290 | F496: 1301 | G496: 1294.5 | H496: 1293.9 | I496: 1295.14 | J496: 1611.8 | K496: 1253.2 | L496: 15695263 | M496: 2.0327587e+10 | N496: 213627 | O496: =(H496-H495)/H495 -> -0.0054573405

Sheet DR.REDDY'S
A1: DATE | B1: SERIES | C1: OPEN | D1: HIGH | E1: LOW | F1: PREV. CLOSE | G1: LTP | H1: CLOSE | I1: VWAP | J1: 52W H | K1: 52W L | L1: VOLUME | M1: VALUE | N1: NO. OF TRADES | O1: Daily Return
A2: 45474 | B2: EQ | C2: 6430 | D2: 6480 | E2: 6337.15 | F2: 6402.35 | G2: 6360 | H2: 6353.7 | I2: 6389.62 | J2: 6505.9 | K2: 5076.25 | L2: 450385 | M2: 2.8777876e+09 | N2: 64101
A3: 45475 | B3: EQ | C3: 6345 | D3: 6380.95 | E3: 6284.25 | F3: 6353.7 | G3: 6364.85 | H3: 6370.25 | I3: 6340.54 | J3: 6505.9 | K3: 5076.25 | L3: 363815 | M3: 2.3067833e+09 | N3: 49459 | O3: =(H3-H2)/H2 -> 0.0026047815
A4: 45476 | B4: EQ | C4: 6374 | D4: 6525.8 | E4: 6365.15 | F4: 6370.25 | G4: 6416.55 | H4: 6425.9 | I4: 6462.92 | J4: 6525.8 | K4: 5076.25 | L4: 582640 | M4: 3765556555 | N4: 59122 | O4: =(H4-H3)/H3 -> 0.0087359209
A5: 45477 | B5: EQ | C5: 6430 | D5: 6542 | E5: 6370.1 | F5: 6425.9 | G5: 6471.1 | H5: 6479.35 | I5: 6458.8 | J5: 6542 | K5: 5076.25 | L5: 348849 | M5: 2.2531451e+09 | N5: 44871 | O5: =(H5-H4)/H4 -> 0.008317901
A6: 45478 | B6: EQ | C6: 6479.35 | D6: 6547.15 | E6: 6456.05 | F6: 6479.35 | G6: 6506.55 | H6: 6520 | I6: 6509.4 | J6: 6547.15 | K6: 5076.25 | L6: 227835 | M6: 1.4830684e+09 | N6: 30599 | O6: =(H6-H5)/H5 -> 0.0062737775
A7: 45481 | B7: EQ | C7: 6520 | D7: 6575 | E7: 6486 | F7: 6520 | G7: 6550 | H7: 6534.15 | I7: 6533.2 | J7: 6575 | K7: 5076.25 | L7: 161476 | M7: 1.0549549e+09 | N7: 24915 | O7: =(H7-H6)/H6 -> 0.0021702454
A8: 45482 | B8: EQ | C8: 6540 | D8: 6595 | E8: 6430.95 | F8: 6534.15 | G8: 6591 | H8: 6582.85 | I8: 6527.66 | J8: 6595 | K8: 5076.25 | L8: 346928 | M8: 2.2646293e+09 | N8: 51152 | O8: =(H8-H7)/H7 -> 0.00745315
A9: 45483 | B9: EQ | C9: 6574.5 | D9: 6604.45 | E9: 6483 | F9: 6582.85 | G9: 6586.95 | H9: 6592.55 | I9: 6557.28 | J9: 6604.45 | K9: 5076.25 | L9: 257510 | M9: 1.6885641e+09 | N9: 37049 | O9: =(H9-H8)/H8 -> 0.0014735259
A10: 45484 | B10: EQ | C10: 6593.15 | D10: 6621.95 | E10: 6534.85 | F10: 6592.55 | G10: 6597.15 | H10: 6594.75 | I10: 6588.4 | J10: 6621.95 | K10: 5076.25 | L10: 316268 | M10: 2.0837013e+09 | N10: 69920 | O10: =(H10-H9)/H9 -> 0.00033371002
A11: 45485 | B11: EQ | C11: 6590.25 | D11: 6745 | E11: 6564.7 | F11: 6594.75 | G11: 6729 | H11: 6719.45 | I11: 6674.98 | J11: 6745 | K11: 5076.25 | L11: 588880 | M11: 3.9307615e+09 | N11: 46918 | O11: =(H11-H10)/H10 -> 0.018908981
A12: 45488 | B12: EQ | C12: 6750 | D12: 6884.95 | E12: 6702.55 | F12: 6719.45 | G12: 6775 | H12: 6794.75 | I12: 6803.98 | J12: 6884.95 | K12: 5093 | L12: 604795 | M12: 4.1150103e+09 | N12: 65074 | O12: =(H12-H11)/H11 -> 0.011206274
A13: 45489 | B13: EQ | C13: 6759.95 | D13: 6782.95 | E13: 6636.65 | F13: 6794.75 | G13: 6650 | H13: 6646.05 | I13: 6689.2 | J13: 6884.95 | K13: 5093 | L13: 311284 | M13: 2.0822416e+09 | N13: 34439 | O13: =(H13-H12)/H12 -> -0.021884543
A14: 45491 | B14: EQ | C14: 6646 | D14: 6708.85 | E14: 6590.4 | F14: 6646.05 | G14: 6655.15 | H14: 6667.5 | I14: 6649.4 | J14: 6884.95 | K14: 5093 | L14: 385707 | M14: 2.5647214e+09 | N14: 57358 | O14: =(H14-H13)/H13 -> 0.003227481
... A496: 46203 | B496: EQ | C496: 1375 | D496: 1375 | E496: 1347.1 | F496: 1375.7 | G496: 1361 | H496: 1357.1 | I496: 1359.97 | J496: 1414.9 | K496: 1148.4 | L496: 2446438 | M496: 3.3270818e+09 | N496: 80649 | O496: =(H496-H495)/H495 -> -0.01352039

Sheet NIFTY50
A1: Date | B1: Open | C1: High | D1: Low | E1: Close | F1: Shares Traded | G1: Turnover (? Cr) | H1: Daily Return
A2: 45474 | B2: 23992.95 | C2: 24164 | D2: 23992.7 | E2: 24141.95 | F2: 242468081 | G2: 28204.06
A3: 45475 | B3: 24228.75 | C3: 24236.35 | D3: 24056.4 | E3: 24123.85 | F3: 309629240 | G3: 34838.65 | H3: =(E3-E2)/E2 -> -0.00074973231
A4: 45476 | B4: 24291.75 | C4: 24309.15 | D4: 24207.1 | E4: 24286.5 | F4: 289201551 | G4: 36661.17 | H4: =(E4-E3)/E3 -> 0.0067422903
A5: 45477 | B5: 24369.95 | C5: 24401 | D5: 24281 | E5: 24302.15 | F5: 251189844 | G5: 28466.6 | H5: =(E5-E4)/E4 -> 0.00064439092
A6: 45478 | B6: 24213.35 | C6: 24363 | D6: 24168.85 | E6: 24323.85 | F6: 298381204 | G6: 32052.48 | H6: =(E6-E5)/E5 -> 0.00089292511
A7: 45481 | B7: 24329.45 | C7: 24344.6 | D7: 24240.55 | E7: 24320.55 | F7: 266299131 | G7: 26356.03 | H7: =(E7-E6)/E6 -> -0.00013566931
A8: 45482 | B8: 24351 | C8: 24443.6 | D8: 24331.9 | E8: 24433.2 | F8: 250537091 | G8: 29361.08 | H8: =(E8-E7)/E7 -> 0.0046318854
A9: 45483 | B9: 24459.85 | C9: 24461.05 | D9: 24141.8 | E9: 24324.45 | F9: 292263786 | G9: 35358.54 | H9: =(E9-E8)/E8 -> -0.0044509111
A10: 45484 | B10: 24396.55 | C10: 24402.65 | D10: 24193.75 | E10: 24315.95 | F10: 306404194 | G10: 32115.44 | H10: =(E10-E9)/E9 -> -0.00034944264
A11: 45485 | B11: 24387.95 | C11: 24592.2 | D11: 24331.15 | E11: 24502.15 | F11: 325823474 | G11: 39565.33 | H11: =(E11-E10)/E10 -> 0.0076575252
A12: 45488 | B12: 24587.6 | C12: 24635.05 | D12: 24522.75 | E12: 24586.7 | F12: 305395934 | G12: 31593.04 | H12: =(E12-E11)/E11 -> 0.0034507176
A13: 45489 | B13: 24615.9 | C13: 24661.25 | D13: 24587.65 | E13: 24613 | F13: 283212233 | G13: 28668.71 | H13: =(E13-E12)/E12 -> 0.001069684
A14: 45491 | B14: 24543.8 | C14: 24837.75 | D14: 24504.45 | E14: 24800.85 | F14: 350924425 | G14: 40477.17 | H14: =(E14-E13)/E13 -> 0.0076321456
... A496: 46203 | B496: 24032.05 | C496: 24035.55 | D496: 23829.2 | E496: 23865.75 | F496: 449044753 | G496: 39507.02 | H496: =(E496-E495)/E495 -> -0.0033616955

Sheet SUMMARY STATISTICS
A1: Stock | B1: Mean Daily Return | C1: Standard Deviation | D1: Beta
A2: HCLTECH | B2: =AVERAGE(HCLTECH!O3:O496) -> -0.00049878007 | C2: =STDEV(HCLTECH!O3:O496) -> 0.016600991 | D2: =_xlfn.COVARIANCE.S(HCLTECH!O3:O496,NIFTY50!H3:H496)/_xlfn.VAR.S(NIFTY50!H3:H496) -> 0.93740914
A3: ITC | B3: =AVERAGE(ITC!O3:O496) -> -0.00073502587 | C3: =STDEV(ITC!O3:O496) -> 0.012510056 | D3: =_xlfn.COVARIANCE.S(ITC!O3:O496,NIFTY50!H3:H496)/_xlfn.VAR.S(NIFTY50!H3:H496) -> 0.63502003
A4: HDFCBANK | B4: =AVERAGE(HDFCBANK!O3:O496) -> -0.0010611127 | C4: =STDEV(HDFCBANK!O3:O496) -> 0.025832503 | D4: =_xlfn.COVARIANCE.S(HDFCBANK!O3:O496,NIFTY50!H3:H496)/_xlfn.VAR.S(NIFTY50!H3:H496) -> 1.1949826
A5: MARUTI | B5: =AVERAGE(MARUTI!O3:O496) -> 0.00041863744 | C5: =STDEV(MARUTI!O3:O496) -> 0.014775893 | D5: =_xlfn.COVARIANCE.S(MARUTI!O3:O496,NIFTY50!H3:H496)/_xlfn.VAR.S(NIFTY50!H3:H496) -> 1.0018339
A6: RELIANCE | B6: =AVERAGE(RELIANCE!O3:O496) -> -0.0013082455 | C6: =STDEV(RELIANCE!O3:O496) -> 0.025998948 | D6: =_xlfn.COVARIANCE.S(RELIANCE!O3:O496,NIFTY50!H3:H496)/_xlfn.VAR.S(NIFTY50!H3:H496) -> 0.95723054
A7: DR.REDDY'S | B7: =AVERAGE('DR.REDDY''S'!O3:O496) -> -0.0014026909 | C7: =STDEV('DR.REDDY''S'!O3:O496) -> 0.038494907 | D7: =_xlfn.COVARIANCE.S('DR.REDDY''S'!O3:O496,NIFTY50!H3:H496)/_xlfn.VAR.S(NIFTY50!H3:H496) -> 0.44224261

Sheet PORTFOLIO ANALYSIS
A1: Portfolio Construction & Performance Analysis
A3: Covariance Matrix (Daily Returns)
B4: HCLTECH | C4: ITC | D4: HDFCBANK | E4: MARUTI | F4: RELIANCE | G4: DR.REDDY'S
A5: HCLTECH | B5: =_xlfn.COVARIANCE.S(HCLTECH!O$3:O$496,HCLTECH!O$3:O$496) -> 0.00027559289 | C5: =_xlfn.COVARIANCE.S(HCLTECH!O$3:O$496,ITC!O$3:O$496) -> 4.3833087e-05 | D5: =_xlfn.COVARIANCE.S(HCLTECH!O$3:O$496,HDFCBANK!O$3:O$496) -> 4.5039268e-05 | E5: =_xlfn.COVARIANCE.S(HCLTECH!O$3:O$496,MARUTI!O$3:O$496) -> 4.3043773e-05 | F5: =_xlfn.COVARIANCE.S(HCLTECH!O$3:O$496,RELIANCE!O$3:O$496) -> 5.1738423e-05 | G5: =_xlfn.COVARIANCE.S(HCLTECH!O$3:O$496,'DR.REDDY''S'!O$3:O$496) -> 1.7360462e-05
A6: ITC | B6: =_xlfn.COVARIANCE.S(ITC!O$3:O$496,HCLTECH!O$3:O$496) -> 4.3833087e-05 | C6: =_xlfn.COVARIANCE.S(ITC!O$3:O$496,ITC!O$3:O$496) -> 0.00015650151 | D6: =_xlfn.COVARIANCE.S(ITC!O$3:O$496,HDFCBANK!O$3:O$496) -> 2.7572995e-05 | E6: =_xlfn.COVARIANCE.S(ITC!O$3:O$496,MARUTI!O$3:O$496) -> 4.4423671e-05 | F6: =_xlfn.COVARIANCE.S(ITC!O$3:O$496,RELIANCE!O$3:O$496) -> 4.7893141e-05 | G6: =_xlfn.COVARIANCE.S(ITC!O$3:O$496,'DR.REDDY''S'!O$3:O$496) -> 1.5748086e-05
A7: HDFCBANK | B7: =_xlfn.COVARIANCE.S(HDFCBANK!O$3:O$496,HCLTECH!O$3:O$496) -> 4.5039268e-05 | C7: =_xlfn.COVARIANCE.S(HDFCBANK!O$3:O$496,ITC!O$3:O$496) -> 2.7572995e-05 | D7: =_xlfn.COVARIANCE.S(HDFCBANK!O$3:O$496,HDFCBANK!O$3:O$496) -> 0.0006673182 | E7: =_xlfn.COVARIANCE.S(HDFCBANK!O$3:O$496,MARUTI!O$3:O$496) -> 4.4962143e-05 | F7: =_xlfn.COVARIANCE.S(HDFCBANK!O$3:O$496,RELIANCE!O$3:O$496) -> 8.4181705e-05 | G7: =_xlfn.COVARIANCE.S(HDFCBANK!O$3:O$496,'DR.REDDY''S'!O$3:O$496) -> 5.4627033e-05
A8: MARUTI | B8: =_xlfn.COVARIANCE.S(MARUTI!O$3:O$496,HCLTECH!O$3:O$496) -> 4.3043773e-05 | C8: =_xlfn.COVARIANCE.S(MARUTI!O$3:O$496,ITC!O$3:O$496) -> 4.4423671e-05 | D8: =_xlfn.COVARIANCE.S(MARUTI!O$3:O$496,HDFCBANK!O$3:O$496) -> 4.4962143e-05 | E8: =_xlfn.COVARIANCE.S(MARUTI!O$3:O$496,MARUTI!O$3:O$496) -> 0.000218327 | F8: =_xlfn.COVARIANCE.S(MARUTI!O$3:O$496,RELIANCE!O$3:O$496) -> 7.3398106e-05 | G8: =_xlfn.COVARIANCE.S(MARUTI!O$3:O$496,'DR.REDDY''S'!O$3:O$496) -> 4.3980092e-05
A9: RELIANCE | B9: =_xlfn.COVARIANCE.S(RELIANCE!O$3:O$496,HCLTECH!O$3:O$496) -> 5.1738423e-05 | C9: =_xlfn.COVARIANCE.S(RELIANCE!O$3:O$496,ITC!O$3:O$496) -> 4.7893141e-05 | D9: =_xlfn.COVARIANCE.S(RELIANCE!O$3:O$496,HDFCBANK!O$3:O$496) -> 8.4181705e-05 | E9: =_xlfn.COVARIANCE.S(RELIANCE!O$3:O$496,MARUTI!O$3:O$496) -> 7.3398106e-05 | F9: =_xlfn.COVARIANCE.S(RELIANCE!O$3:O$496,RELIANCE!O$3:O$496) -> 0.0006759453 | G9: =_xlfn.COVARIANCE.S(RELIANCE!O$3:O$496,'DR.REDDY''S'!O$3:O$496) -> 0.00084252882
A10: DR.REDDY'S | B10: =_xlfn.COVARIANCE.S('DR.REDDY''S'!O$3:O$496,HCLTECH!O$3:O$496) -> 1.7360462e-05 | C10: =_xlfn.COVARIANCE.S('DR.REDDY''S'!O$3:O$496,ITC!O$3:O$496) -> 1.5748086e-05 | D10: =_xlfn.COVARIANCE.S('DR.REDDY''S'!O$3:O$496,HDFCBANK!O$3:O$496) -> 5.4627033e-05 | E10: =_xlfn.COVARIANCE.S('DR.REDDY''S'!O$3:O$496,MARUTI!O$3:O$496) -> 4.3980092e-05 | F10: =_xlfn.COVARIANCE.S('DR.REDDY''S'!O$3:O$496,RELIANCE!O$3:O$496) -> 0.00084252882 | G10: =_xlfn.COVARIANCE.S('DR.REDDY''S'!O$3:O$496,'DR.REDDY''S'!O$3:O$496) -> 0.0014818579
A13: Minimum Variance Portfolio (via matrix inversion: w = Sigma^-1 * 1 / (1^T Sigma^-1 1))
A14: Inverse Covariance Matrix
B15: HCLTECH | C15: ITC | D15: HDFCBANK | E15: MARUTI | F15: RELIANCE | G15: DR.REDDY'S | H15: Ones | I15: Sigma^-1 * 1 | J15: MinVar Weight
A16: HCLTECH | B16: {=MINVERSE(B5:G10)} -> 3935.5707 | C16: -812.79592 | D16: -158.20091 | E16: -458.92807 | F16: -520.58774 | G16: 277.97036 | H16: 1 | I16: {=MMULT(B16:G21,H16:H21)} -> 2263.0284 | J16: =I16/SUM($I$16:$I$21) -> 0.20082375
A17: ITC | B17: -812.79592 | C17: 7177.1342 | D17: -91.03979 | E17: -1061.9526 | F17: -960.90181 | G17: 514.45545 | H17: 1 | I17: 4764.8995 | J17: =I17/SUM($I$16:$I$21) -> 0.42284267
A18: HDFCBANK | B18: -158.20091 | C18: -91.03979 | D18: 1555.329 | E18: -189.50706 | F18: -321.37793 | G18: 133.83324 | H18: 1 | I18: 929.03658 | J18: =I18/SUM($I$16:$I$21) -> 0.082443777
A19: MARUTI | B19: -458.92807 | C19: -1061.9526 | D19: -189.50706 | E19: 5153.1082 | F19: -907.69824 | G19: 386.79207 | H19: 1 | I19: 2921.8143 | J19: =I19/SUM($I$16:$I$21) -> 0.25928517
A20: RELIANCE | B20: -520.58774 | C20: -960.90181 | D20: -321.37793 | E20: -907.69824 | F20: 5688.8058 | G20: -3179.3442 | H20: 1 | I20: -201.1041 | J20: =I20/SUM($I$16:$I$21) -> -0.017846209
A21: DR.REDDY'S | B21: 277.97036 | C21: 514.45545 | D21: 133.83324 | E21: 386.79207 | F21: -3179.3442 | G21: 2457.3474 | H21: 1 | I21: 591.05435 | J21: =I21/SUM($I$16:$I$21) -> 0.052450844
A23: Minimum Variance Portfolio - Expected Daily Return | B23: =SUMPRODUCT(J16:J21,'SUMMARY STATISTICS'!B2:B7) -> -0.00044012794
A24: Minimum Variance Portfolio - Daily Variance (= 1/(1^T Sigma^-1 1)) | B24: =1/SUM(I16:I21) -> 8.8741152e-05
A25: Minimum Variance Portfolio - Daily Std Dev | B25: =SQRT(B24) -> 0.0094202523
A28: Value-Weighted Portfolio (weights by Market Capitalization)
A29: Stock | B29: Market Cap (Rs Cr) | C29: Weight
A30: HCLTECH | B30: 369738 | C30: =B30/SUM($B$30:$B$35) -> 0.088054808
A31: ITC | B31: 358783 | C31: =B31/SUM($B$30:$B$35) -> 0.085445824
A32: HDFCBANK | B32: 1157390 | C32: =B32/SUM($B$30:$B$35) -> 0.27563776
A33: MARUTI | B33: 443265 | C33: =B33/SUM($B$30:$B$35) -> 0.1055656
A34: RELIANCE | B34: 1772086 | C34: =B34/SUM($B$30:$B$35) -> 0.42203044
A35: DR.REDDY'S | B35: 97691 | C35: =B35/SUM($B$30:$B$35) -> 0.023265562
A37: Value-Weighted Portfolio - Expected Daily Return | B37: =SUMPRODUCT(C30:C35,'SUMMARY STATISTICS'!B2:B7) -> -0.0009397677
A38: Value-Weighted Portfolio - Daily Variance | B38: {=MMULT(MMULT(TRANSPOSE(C30:C35),B5:G10),C30:C35)} -> 0.00023699077
A39: Value-Weighted Portfolio - Daily Std Dev | B39: =SQRT(B38) -> 0.015394504
A42: Price-Weighted Portfolio (weights by latest closing price)
A43: Stock | B43: Latest Close Price | C43: Weight
A44: HCLTECH | B44: =HCLTECH!H496 -> 1071.8 | C44: =B44/SUM($B$44:$B$49) -> 0.056640966
A45: ITC | B45: =ITC!H496 -> 286.95 | C45: =B45/SUM($B$44:$B$49) -> 0.015164326
A46: HDFCBANK | B46: =HDFCBANK!H496 -> 797.95 | C46: =B46/SUM($B$44:$B$49) -> 0.042168929
A47: MARUTI | B47: =MARUTI!H496 -> 14115 | C47: =B47/SUM($B$44:$B$49) -> 0.74592949
A48: RELIANCE | B48: =RELIANCE!H496 -> 1293.9 | C48: =B48/SUM($B$44:$B$49) -> 0.068378191
A49: DR.REDDY'S | B49: ='DR.REDDY''S'!H496 -> 1357.1 | C49: =B49/SUM($B$44:$B$49) -> 0.071718095
...

Sheet PRICE-VOLUME ANALYSIS
A1: Price-Volume Analysis (2-Year Daily Data)
A3: Correlation between Daily Price and Daily Volume
A4: Stock | B4: Corr(Close, Volume)
A5: HCLTECH | B5: =CORREL(HCLTECH!H2:H496,HCLTECH!L2:L496) -> -0.20637792
A6: ITC | B6: =CORREL(ITC!H2:H496,ITC!L2:L496) -> -0.1243328
A7: HDFCBANK | B7: =CORREL(HDFCBANK!H2:H496,HDFCBANK!L2:L496) -> -0.46336788
A8: MARUTI | B8: =CORREL(MARUTI!H2:H496,MARUTI!L2:L496) -> -0.075466155
A9: RELIANCE | B9: =CORREL(RELIANCE!H2:H496,RELIANCE!L2:L496) -> -0.39282347
A10: DR.REDDY'S | B10: =CORREL('DR.REDDY''S'!H2:H496,'DR.REDDY''S'!L2:L496) -> -0.3991124
A12: Analysis and comments on the relationship between price movement and trading volume for each stock
A13: All six stocks show a negative correlation between daily closing price and daily trading volume over the 2-year period, meaning volume tends to be higher on days when prices are lower, and vice versa. This is a common pattern for large, liquid stocks: participants tend to trade more actively (higher volume) during sell-offs or corrections, while volume typically eases off as prices grind higher, since fewer investors are willing to sell into a rally. HDFC Bank (-0.46) and Dr. Reddy's (-0.40) show the strongest negative relationship, suggesting these stocks saw the most pronounced volume spikes during their price declines - possibly linked to company-specific or sector news that triggered heavier selling. Reliance (-0.39) shows a similarly strong pattern. ITC (-0.12) and Maruti (-0.08) show only weak negative correlation, indicating their trading volume was more evenly distributed across price levels and less driven by sharp sell-offs - consistent with them being viewed as relatively more stable, lower-beta stocks over this period (see Summary Statistics sheet). HCL Tech (-0.21) falls in between, with a moderate tendency for volume to rise on down-days. Overall, the pattern across all 6 stocks supports the general market observation that volume is a better signal of investor anxiety/selling pressure than of bullish conviction in this sample period, which aligns with the broadly negative average daily returns most of these stocks posted (see Summary Statistics).

Sheet CAPM
A1: Capital Asset Pricing Model (CAPM)
A3: Risk-Free Rate (Rf) - annualized, 10Y India G-Sec yield | B3: 0.0681 | C3: Source: tradingeconomics.com, India 10Y G-Sec yield, 31 Jul 2026
A4: Market Return (Rm) - annualized Nifty 50 mean daily return x 252 | B4: =(1+AVERAGE(NIFTY50!H3:H496))^252-1 -> 0.0030365225
A5: Market Risk Premium (Rm - Rf) | B5: =B4-B3 -> -0.065063477
A7: Stock | B7: Mean Daily Return | C7: Annualized Return | D7: Beta | E7: CAPM Required Return = Rf + Beta*(Rm-Rf)
A8: HCLTECH | B8: ='SUMMARY STATISTICS'!B2 -> -0.00049878007 | C8: =(1+B8)^252-1 -> -0.11814174 | D8: ='SUMMARY STATISTICS'!D2 -> 0.93740914 | E8: =$B$3+D8*$B$5 -> 0.0071089017
A9: ITC | B9: ='SUMMARY STATISTICS'!B3 -> -0.00073502587 | C9: =(1+B9)^252-1 -> -0.16914054 | D9: ='SUMMARY STATISTICS'!D3 -> 0.63502003 | E9: =$B$3+D9*$B$5 -> 0.026783388
A10: HDFCBANK | B10: ='SUMMARY STATISTICS'!B4 -> -0.0010611127 | C10: =(1+B10)^252-1 -> -0.23474209 | D10: ='SUMMARY STATISTICS'!D4 -> 1.1949826 | E10: =$B$3+D10*$B$5 -> -0.0096497205
A11: MARUTI | B11: ='SUMMARY STATISTICS'!B5 -> 0.00041863744 | C11: =(1+B11)^252-1 -> 0.11123783 | D11: ='SUMMARY STATISTICS'!D5 -> 1.0018339 | E11: =$B$3+D11*$B$5 -> 0.0029172051
A12: RELIANCE | B12: ='SUMMARY STATISTICS'!B6 -> -0.0013082455 | C12: =(1+B12)^252-1 -> -0.28099984 | D12: ='SUMMARY STATISTICS'!D6 -> 0.95723054 | E12: =$B$3+D12*$B$5 -> 0.0058192521
A13: DR.REDDY'S | B13: ='SUMMARY STATISTICS'!B7 -> -0.0014026909 | C13: =(1+B13)^252-1 -> -0.29793287 | D13: ='SUMMARY STATISTICS'!D7 -> 0.44224261 | E13: =$B$3+D13*$B$5 -> 0.039326158

Sheet BONDS
A1: Section IV: Bonds
A3: IV.a - Bond Data Collection (NSE)
A5: Field | B5: Short-Term G-Sec | C5: Long-Term G-Sec | D5: Corporate NCD
A6: Bond Name | B6: 06.36 GS 2031 | C6: 06.68 GS 2040 | D6: 769NHAI31
A7: Issuer | B7: Government of India | C7: Government of India | D7: NHAI
A8: Category | B8: Short-Term G-Sec | C8: Long-Term G-Sec | D8: Corporate NCD
A9: Coupon Rate | B9: 0.0636 | C9: 0.0668 | D9: 0.0769
A10: Face Value (Rs) | B10: 100 | C10: 100 | D10: 1000
A11: Last Traded Price (Rs) | B11: 99.75 | C11: 96.99 | D11: 1144.15
A12: Yield | B12: 0.064237 | C12: 0.070215
A13: Volume Traded | B13: 1,295.00 Cr (141 trades) | C13: 1,520.00 Cr (175 trades) | D13: 1770
A14: Approx. Maturity Year | B14: 2031 | C14: 2040 | D14: 2031
A15: Current Yield (approx.) for Corporate NCD = Coupon x Face Value / Price | D15: =D9*D10/D11 -> 0.067211467
A16: Note: True Yield to Maturity for the NCD requires exact maturity date & cash flow schedule from NSE; current yield used as an approximation here.
A18: Remaining Maturity (Years, approx., from Aug 2026) | B18: =B14-2026 -> 5 | C18: =C14-2026 -> 14 | D18: =D14-2026 -> 5
A21: IV.b - Bond Price-Yield Analysis (RBI Retail Direct - G-Secs of Different Maturities)
A22: Source: RBI Retail Direct, Top Market Data, 04 Aug 2026
A24: Bond Name | B24: Coupon Rate | C24: Price | D24: Yield to Maturity | E24: Maturity Year | F24: Years to Maturity (approx.)
A25: 06.94 GS 2036 | B25: 0.0694 | C25: 100.7275 | D25: 0.068346 | E25: 2036 | F25: =E25-2026 -> 10
A26: 06.36 GS 2031 | B26: 0.0636 | C26: 99.75 | D26: 0.064237 | E26: 2031 | F26: =E26-2026 -> 5
A27: 06.54 GS 2032 | B27: 0.0654 | C27: 100.23 | D27: 0.064882 | E27: 2032 | F27: =E27-2026 -> 6
A28: 06.68 GS 2040 | B28: 0.0668 | C28: 96.99 | D28: 0.070215 | E28: 2040 | F28: =E28-2026 -> 14
A29: 06.68 GS 2033 | B29: 0.0668 | C29: 100.3 | D29: 0.066219 | E29: 2033 | F29: =E29-2026 -> 7
A32: Answers
A33: Highest Coupon Rate security | B33: =INDEX(A25:A29,MATCH(MAX(B25:B29),B25:B29,0)) -> 06.94 GS 2036 | C33: =MAX(B25:B29) -> 0.0694
A34: Lowest Coupon Rate security | B34: =INDEX(A25:A29,MATCH(MIN(B25:B29),B25:B29,0)) -> 06.36 GS 2031 | C34: =MIN(B25:B29) -> 0.0636
A35: Highest Yield to Maturity security | B35: =INDEX(A25:A29,MATCH(MAX(D25:D29),D25:D29,0)) -> 06.68 GS 2040 | C35: =MAX(D25:D29) -> 0.070215
A36: Lowest Yield to Maturity security | B36: =INDEX(A25:A29,MATCH(MIN(D25:D29),D25:D29,0)) -> 06.36 GS 2031 | C36: =MIN(D25:D29) -> 0.064237
A37: Longest Remaining Maturity security | B37: =INDEX(A25:A29,MATCH(MAX(F25:F29),F25:F29,0)) -> 06.68 GS 2040 | C37: =MAX(F25:F29) -> 14
A40: Trading Data (for a given date - 04 Aug 2026, RBI Retail Direct)
A42: Field | B42: Short-Term G-Sec (06.36 GS 2031) | C42: Long-Term G-Sec (06.68 GS 2040) | D42: Corporate NCD (769NHAI31)
A43: Buy (Bid) Price | B43: 99.74 | C43: 96.975 | D43: 1146
A44: Buy (Bid) Quantity | B44: 20 | C44: 10 | D44: 200
A45: Sell (Offer/Ask) Price | B45: 99.75 | C45: 96.99 | D45: 1149
A46: Sell (Offer/Ask) Quantity | B46: 5 | C46: 10 | D46: 5
A47: High Price (day) | B47: 99.81 | C47: 97.175 | D47: 1145.25
A48: Low Price (day) | B48: 99.74 | C48: 96.9625 | D48: 1144.15
A49: Volume Traded | B49: 1,295.00 Cr (141 trades) | C49: 1,520.00 Cr (175 trades) | D49: 1770
A50: Previous Close | D50: 1150.99
A51: VWAP (optional) | D51: 1144.41
...
